<robot name="test_robot">

## links
  <link name="base_link">
   <visual>
    <geometry>
      <box size="1 1 0.1" />
    </geometry>
   </visual>
   <collision>
    <geometry>
      <box size="1 1 0.1" />
    </geometry>
   </collision>	
  </link>
  
  <link name="link1" >
   <visual>
    <geometry>
      <box size="0.2 0.2 0.3" />
    </geometry>
    <origin rpy="0 1.57 0" xyz="0.15 0 0" />
   </visual>
   <collision>
    <geometry>
      <box size="0.2 0.2 0.3" />
    </geometry>
   </collision>	
  </link>
  
  <link name="link2">
   <visual>
    <geometry>
      <box size="0.2 0.2 1" />
    </geometry>
    <origin rpy="0 0 0" xyz="0 0 0.4" />
   </visual>
   <collision>
    <geometry>
      <box size="0.2 0.2 1" />
    </geometry>
   </collision>	
  </link>
  
  <link name="link3">
   <visual>
    <geometry>
      <box size="0.2 0.2 1" />
    </geometry>
    <origin rpy="0 0 0" xyz="0 0 0.4" />
   </visual>
   <collision>
    <geometry>
      <box size="0.2 0.2 1" />
    </geometry>
   </collision>	
  </link>

  <link name="link4">
   <visual>
    <geometry>
      <box size="0.2 0.2 0.2" />
    </geometry>
    <origin rpy="0 0 0" xyz="0 0 0" />
   </visual>
   <collision>
    <geometry>
      <box size="0.2 0.2 0.2" />
    </geometry>
   </collision>	
  </link>

  <link name="link5">
   <visual>
    <geometry>
      <box size="0.2 0.2 0.2" />
    </geometry>
    <origin rpy="0 0 0" xyz="0.1 0 0" />
   </visual>
   <collision>
    <geometry>
      <box size="0.2 0.2 0.2" />
    </geometry>
   </collision>	
  </link>

  <link name="link6">
   <visual>
    <geometry>
      <box size="0.2 0.2 0.2" />
    </geometry>
    <origin rpy="0 0 0" xyz="0.1 0 0" />
   </visual>
   <collision>
    <geometry>
      <box size="0.2 0.2 0.2" />
    </geometry>
   </collision>	
  </link>


## end links


##joints
##joint1
  <joint name="joint1" type="continuous">
    <parent link="base_link"/>
    <child link="link1"/>
    <limit effort="1000.0" lower="-0.5" upper="0" velocity="0.5"/>
    <origin xyz="0 0 0.05" rpy="0 -1.57 0" />
  </joint>

##joint2
  <joint name="joint2" type="continuous">
    <parent link="link1"/>
    <child link="link2"/>
    <origin xyz="0.2 0 0.2" rpy="0 1.57 0" />
  </joint>

##joint3
  <joint name="joint3" type="continuous">
    <parent link="link2"/>
    <child link="link3"/>
    <origin xyz="0.2 0 0.8" rpy="0 0 0" />
  </joint>

  ##joint4
  <joint name="joint4" type="continuous">
    <parent link="link3"/>
    <child link="link4"/>
    <origin xyz="-0.2 0 0.8" rpy="0 0 0" />
  </joint>

  ##joint5
  <joint name="joint5" type="continuous">
    <parent link="link4"/>
    <child link="link5"/>
    <origin xyz="0 0 0.1" rpy="0 -1.57 0" />
  </joint>

  ##joint6
  <joint name="joint6" type="continuous">
    <parent link="link5"/>
    <child link="link6"/>
    <origin xyz="0.1 0.1 0" rpy="0 0 1.57" />
  </joint>
</robot>
